[0;33m--- esp-idf-monitor 1.3.1 on /dev/ttyUSB0 115200 ---[0m
[0;33m--- Quit: Ctrl+] | Menu: Ctrl+T | Help: Ctrl+T followed by Ctrl+H ---[0m
[0;33m0x40080400: _init at ??:?
[0m
[0;33m0x400d8475: s_dac_dma_periph_set_clock at /home/matiasnd/esp/esp-idf/components/driver/dac/esp32/dac_dma.c:93
[0m
[0;33m0x4000c46c: memset in ROM
[0m
[0;33m0x4000c477: memset in ROM
[0m
[0;33m0x400d8472: s_dac_dma_periph_set_clock at /home/matiasnd/esp/esp-idf/components/driver/dac/esp32/dac_dma.c:91
[0m
[0;33m0x400d8671: dac_dma_periph_init at /home/matiasnd/esp/esp-idf/components/driver/dac/esp32/dac_dma.c:126
[0m
[0;33m0x400d793e: dac_continuous_new_channels at /home/matiasnd/esp/esp-idf/components/driver/dac/dac_continuous.c:247 (discriminator 2)
[0m
[0;33m0x400d581b: dac_dma_write_task at /home/matiasnd/awg/ESP_code/main/main.c:117 (discriminator 2)
[0m
[0;33m0x40087a3d: vPortTaskWrapper at /home/matiasnd/esp/esp-idf/components/freertos/FreeRTOS-Kernel/portable/xtensa/port.c:162
[0m
[0;33m0x40080400: _init at ??:?
[0m
[1;31mNone[0m
[0;33mWaiting for the device to reconnect[0mException in thread Thread-2 (_run_outer):
Traceback (most recent call last):
  File "/home/matiasnd/.espressif/python_env/idf5.2_py3.10_env/lib/python3.10/site-packages/esp_idf_monitor/base/serial_reader.py", line 76, in run
    data = self.serial.read(self.serial.in_waiting or 1)
  File "/home/matiasnd/.espressif/python_env/idf5.2_py3.10_env/lib/python3.10/site-packages/serial/serialposix.py", line 595, in read
    raise SerialException(
serial.serialutil.SerialException: device reports readiness to read but returned no data (device disconnected or multiple access on port?)

During handling of the above exception, another exception occurred:

Traceback (most recent call last):
  File "/home/matiasnd/.espressif/python_env/idf5.2_py3.10_env/lib/python3.10/site-packages/esp_idf_monitor/base/serial_reader.py", line 83, in run
    self.close_serial()
  File "/home/matiasnd/.espressif/python_env/idf5.2_py3.10_env/lib/python3.10/site-packages/esp_idf_monitor/base/serial_reader.py", line 104, in close_serial
    self._disable_closing_wait_or_discard_data()
  File "/home/matiasnd/.espressif/python_env/idf5.2_py3.10_env/lib/python3.10/site-packages/esp_idf_monitor/base/serial_reader.py", line 119, in _disable_closing_wait_or_discard_data
    buf = fcntl.ioctl(self.serial.fd, termios.TIOCGSERIAL, buf)
OSError: [Errno 5] Input/output error

During handling of the above exception, another exception occurred:

Traceback (most recent call last):
  File "/usr/lib/python3.10/threading.py", line 1016, in _bootstrap_inner
    self.run()
  File "/usr/lib/python3.10/threading.py", line 953, in run
    self._target(*self._args, **self._kwargs)
  File "/home/matiasnd/.espressif/python_env/idf5.2_py3.10_env/lib/python3.10/site-packages/esp_idf_monitor/base/stoppable_thread.py", line 47, in _run_outer
    self.run()
  File "/home/matiasnd/.espressif/python_env/idf5.2_py3.10_env/lib/python3.10/site-packages/esp_idf_monitor/base/serial_reader.py", line 100, in run
    self.close_serial()
  File "/home/matiasnd/.espressif/python_env/idf5.2_py3.10_env/lib/python3.10/site-packages/esp_idf_monitor/base/serial_reader.py", line 104, in close_serial
    self._disable_closing_wait_or_discard_data()
  File "/home/matiasnd/.espressif/python_env/idf5.2_py3.10_env/lib/python3.10/site-packages/esp_idf_monitor/base/serial_reader.py", line 119, in _disable_closing_wait_or_discard_data
    buf = fcntl.ioctl(self.serial.fd, termios.TIOCGSERIAL, buf)
OSError: [Errno 5] Input/output error
[0m
